I'm sorry, but an uncaught exception occurred.

While running game code:
  File "game/script.rpy", line 191, in script
    P "We all know that there is a recycling spot in the postal service spot of our campus..."
Exception: Sayer 'P' is not defined.

-- Full Traceback ------------------------------------------------------------

Full traceback:
  File "game/script.rpy", line 191, in script
    P "We all know that there is a recycling spot in the postal service spot of our campus..."
  File "/home/patrick/application/renpy-8.3.2-sdk/renpy/ast.py", line 2573, in execute
    Say.execute(self)
  File "/home/patrick/application/renpy-8.3.2-sdk/renpy/ast.py", line 575, in execute
    who = eval_who(self.who, self.who_fast)
  File "/home/patrick/application/renpy-8.3.2-sdk/renpy/ast.py", line 464, in eval_who
    raise Exception("Sayer '%s' is not defined." % who)
Exception: Sayer 'P' is not defined.

Linux-6.8.0-48-generic-x86_64-with-glibc2.39 x86_64
Ren'Py 8.3.2.24090902
The Invisible Problem 0.9_beta
Tue Nov  5 01:47:37 2024
